<?xml version="1.0" ?>
<!-- =================================================================================== -->
<!-- |    This document was autogenerated by xacro from arm.urdf.xacro                 | -->
<!-- |    EDITING THIS FILE BY HAND IS NOT RECOMMENDED                                 | -->
<!-- =================================================================================== -->
<robot name="arm" xmlns:controller="http://playerstage.sourceforge.net/gazebo/xmlschema/#controller" xmlns:interface="http://playerstage.sourceforge.net/gazebo/xmlschema/#interface" xmlns:sensor="http://playerstage.sourceforge.net/gazebo/xmlschema/#sensor" xmlns:xacro="http://ros.org/wiki/xacro">
  <link name="base_link">
    <origin rpy="0 0 0" xyz="0 0 0"/>
  </link>
  <material name="Schunk/LightGrey">
    <color rgba="0.7 0.7 0.7 1.0"/>
  </material>
  <material name="Schunk/DarkGrey">
    <color rgba="0.2 0.2 0.2 1.0"/>
  </material>
  <material name="Schunk/Blue">
    <color rgba="0.0 0.0 0.25 1.0"/>
  </material>
  <material name="Schunk/Yellow">
    <color rgba="0.25 0.25 0.0 1.0"/>
  </material>
  <joint name="table_base_joint" type="fixed">
    <origin rpy="0 0 0" xyz="0 0 0"/>
    <parent link="base_link"/>
    <child link="table_link"/>
  </joint>
  <!-- joint between base_link and arm_0_link -->
  <joint name="arm_0_joint" type="fixed">
    <origin rpy="0 0 0" xyz="0 0 0"/>
    <parent link="table_link"/>
    <child link="arm_0_link"/>
  </joint>
  <joint name="camera_base_joint" type="fixed">
    <origin rpy="0 0 0" xyz="0 0 0"/>
    <parent link="base_link"/>
    <child link="camera_link"/>
  </joint>
  <link name="camera_link">
    <inertial>
      <origin rpy="0 0 0" xyz="0 0 0"/>
      <mass value="10"/>
      <inertia ixx="0.01" ixy="0" ixz="0" iyy="0.01" iyz="0" izz="0.01"/>
    </inertial>
    <visual>
      <origin rpy="1.57 0 0" xyz="0 0 -0.01"/>
      <geometry>
        <mesh filename="package://schunk_gripper_communication/meshes/cylinder-notop.dae" scale="1.85 0.2 1.85"/>
      </geometry>
      <material name="Schunk/Yellow"/>
    </visual>
    <collision>
      <origin rpy="1.57 0 0" xyz="0 0 -0.01"/>
      <geometry>
        <mesh filename="package://schunk_gripper_communication/meshes/cylinder-notop.dae" scale="1.85 0.2 1.85"/>
      </geometry>
    </collision>
  </link>
  <link name="table_link">
    <inertial>
      <origin rpy="0 0 0" xyz="0 0 0"/>
      <mass value="10"/>
      <inertia ixx="0.01" ixy="0" ixz="0" iyy="0.01" iyz="0" izz="0.01"/>
    </inertial>
    <visual>
      <origin rpy="0 0 0" xyz="0 0 -0.01"/>
      <geometry>
        <cylinder length="0.01" radius="0.9"/>
      </geometry>
      <material name="Schunk/Yellow"/>
    </visual>
    <collision>
      <origin rpy="0 0 0" xyz="0 0 -0.01"/>
      <geometry>
        <cylinder length="0.01" radius="0.9"/>
      </geometry>
    </collision>
  </link>
  <link name="arm_0_link">
    <inertial>
      <origin rpy="0 0 0" xyz="0 0 0"/>
      <mass value="0.29364"/>
      <inertia ixx="0.01" ixy="0" ixz="0" iyy="0.01" iyz="0" izz="0.01"/>
    </inertial>
    <visual>
      <origin rpy="0 0 0" xyz="0 0 0"/>
      <geometry>
        <mesh filename="package://schunk_gripper_communication/meshes/lwa4p/arm_0_link.dae"/>
      </geometry>
      <material name="Schunk/DarkGrey"/>
    </visual>
    <collision>
      <origin rpy="0 0 0" xyz="0 0 0"/>
      <geometry>
        <mesh filename="package://schunk_gripper_communication/meshes/lwa4p/arm_0_link.stl"/>
      </geometry>
    </collision>
  </link>
  <joint name="arm_1_joint" type="revolute">
    <origin rpy="0 0 0" xyz="0 0 0.11"/>
    <parent link="arm_0_link"/>
    <child link="arm_1_link"/>
    <axis xyz="0 0 1"/>
    <calibration rising="2.1"/>
    <limit effort="0.1" lower="-2.95" upper="2.95" velocity="1.25"/>
  </joint>
  <link name="arm_1_link">
    <inertial>
      <mass value="0.29364"/>
      <inertia ixx="0.01" ixy="0" ixz="0" iyy="0.01" iyz="0" izz="0.01"/>
      <origin rpy="0 0 0" xyz="0 0 0"/>
    </inertial>
    <!--
      <inertial>
        <origin xyz="0 0 0" rpy="0 0 0" />
        <mass value="0.29364"/>
        <inertia ixx="0.01" ixy="0" ixz="0" iyy="0.01" iyz="0" izz="0.01" />
      </inertial>
-->
    <visual>
      <origin rpy="0 0 0" xyz="0 0 0"/>
      <geometry>
        <mesh filename="package://schunk_gripper_communication/meshes/lwa4p/arm_1_link.dae"/>
      </geometry>
      <material name="Schunk/DarkGrey"/>
    </visual>
    <collision>
      <origin rpy="0 0 0" xyz="0 0 0"/>
      <geometry>
        <mesh filename="package://schunk_gripper_communication/meshes/lwa4p/arm_1_link.stl"/>
      </geometry>
    </collision>
  </link>
  <!-- joint between arm_1_link and arm_2_link -->
  <joint name="arm_2_joint" type="revolute">
    <origin rpy="1.5708 0 0" xyz="0 0 0"/>
    <parent link="arm_1_link"/>
    <child link="arm_2_link"/>
    <axis xyz="0 0 1"/>
    <limit effort="0.1" lower="-2.95" upper="2.95" velocity="1.25"/>
    <!-- This is useful when the arm is mounted standing on a table -->
    <!-- <safety_controller k_position="20" k_velocity="25" soft_lower_limit="${-1.9 + safety_offset}" soft_upper_limit="${1.9 - safety_offset}" /> -->
  </joint>
  <link name="arm_2_link">
    <inertial>
      <mass value="0.29364"/>
      <inertia ixx="0.01" ixy="0" ixz="0" iyy="0.01" iyz="0" izz="0.01"/>
      <origin rpy="0 0 0" xyz="0 0 0"/>
    </inertial>
    <!--
      <inertial>
        <origin xyz="0 0 0" rpy="0 0 0"/>
        <mass value="1.68311"/>
        <inertia ixx="0.03" ixy="0" ixz="0" iyy="0.03" iyz="0" izz="0.03" />
      </inertial>
-->
    <visual>
      <origin rpy="0 0 0" xyz="0 0 0"/>
      <geometry>
        <mesh filename="package://schunk_gripper_communication/meshes/lwa4p/arm_2_link.dae"/>
      </geometry>
      <material name="Schunk/Blue"/>
    </visual>
    <collision>
      <origin rpy="0 0 0" xyz="0 0 0"/>
      <geometry>
        <mesh filename="package://schunk_gripper_communication/meshes/lwa4p/arm_2_link.stl"/>
      </geometry>
    </collision>
  </link>
  <!-- joint between arm_2_link and arm_3_link -->
  <joint name="arm_3_joint" type="revolute">
    <origin rpy="0 3.14159 0" xyz="0 0.350 0"/>
    <parent link="arm_2_link"/>
    <child link="arm_3_link"/>
    <axis xyz="0 0 1"/>
    <limit effort="0.1" lower="-2.95" upper="2.95" velocity="1.25"/>
    <safety_controller k_position="20" k_velocity="25" soft_lower_limit="-2.68" soft_upper_limit="2.68"/>
  </joint>
  <link name="arm_3_link">
    <inertial>
      <mass value="0.29364"/>
      <inertia ixx="0.01" ixy="0" ixz="0" iyy="0.01" iyz="0" izz="0.01"/>
      <origin rpy="0 0 0" xyz="0 0 0"/>
    </inertial>
    <!--
      <inertial>
        <origin xyz="0 0 0" rpy="0 0 0"/>
        <mass value="2.1"/>
        <inertia ixx="0.03" ixy="0" ixz="0" iyy="0.03" iyz="0" izz="0.03" />
      </inertial>
-->
    <visual>
      <origin rpy="0 0 0" xyz="0 0 0"/>
      <geometry>
        <mesh filename="package://schunk_gripper_communication/meshes/lwa4p/arm_3_link.dae"/>
      </geometry>
      <material name="Schunk/DarkGrey"/>
    </visual>
    <collision>
      <origin rpy="0 0 0" xyz="0 0 0"/>
      <geometry>
        <mesh filename="package://schunk_gripper_communication/meshes/lwa4p/arm_3_link.stl"/>
      </geometry>
    </collision>
  </link>
  <!-- joint between arm_3_link and arm_4_link -->
  <joint name="arm_4_joint" type="revolute">
    <origin rpy="-1.5708 3.14159 0" xyz="0 0 0"/>
    <parent link="arm_3_link"/>
    <child link="arm_4_link"/>
    <axis xyz="0 0 1"/>
    <limit effort="0.1" lower="-2.95" upper="2.95" velocity="1.25"/>
  </joint>
  <link name="arm_4_link">
    <inertial>
      <mass value="0.29364"/>
      <inertia ixx="0.01" ixy="0" ixz="0" iyy="0.01" iyz="0" izz="0.01"/>
      <origin rpy="0 0 0" xyz="0 0 0"/>
    </inertial>
    <!--
      <inertial>
        <origin xyz="0 0 0" rpy="0 0 0"/>
        <mass value="1.68311"/>
        <inertia ixx="0.03" ixy="0" ixz="0" iyy="0.03" iyz="0" izz="0.03" />
      </inertial>
-->
    <visual>
      <origin rpy="0 0 0" xyz="0 0 0"/>
      <geometry>
        <mesh filename="package://schunk_gripper_communication/meshes/lwa4p/arm_4_link.dae"/>
      </geometry>
      <material name="Schunk/Blue"/>
    </visual>
    <collision>
      <origin rpy="0 0 0" xyz="0 0 0"/>
      <geometry>
        <mesh filename="package://schunk_gripper_communication/meshes/lwa4p/arm_4_link.stl"/>
      </geometry>
    </collision>
  </link>
  <!-- joint between arm_4_link and arm_5_link -->
  <joint name="arm_5_joint" type="revolute">
    <origin rpy="1.5708 0 3.14159" xyz="0 0.005263 0.305"/>
    <parent link="arm_4_link"/>
    <child link="arm_5_link"/>
    <axis xyz="0 0 1"/>
    <limit effort="0.1" lower="-2.95" upper="2.95" velocity="1.25"/>
  </joint>
  <link name="arm_5_link">
    <inertial>
      <mass value="0.29364"/>
      <inertia ixx="0.01" ixy="0" ixz="0" iyy="0.01" iyz="0" izz="0.01"/>
      <origin rpy="0 0 0" xyz="0 0 0"/>
    </inertial>
    <!--
      <inertial>
        <origin xyz="0 0 0" rpy="0 0 0"/>
        <mass value="0.807"/>
        <inertia ixx="0.03" ixy="0" ixz="0" iyy="0.03" iyz="0" izz="0.03" />
      </inertial>
-->
    <visual>
      <origin rpy="0 0 0" xyz="0 0 0"/>
      <geometry>
        <mesh filename="package://schunk_gripper_communication/meshes/lwa4p/arm_5_link.dae"/>
      </geometry>
      <material name="Schunk/DarkGrey"/>
    </visual>
    <collision>
      <origin rpy="0 0 0" xyz="0 0 0"/>
      <geometry>
        <mesh filename="package://schunk_gripper_communication/meshes/lwa4p/arm_5_link.stl"/>
      </geometry>
    </collision>
  </link>
  <!-- joint between arm_5_link and arm_6_link -->
  <joint name="arm_6_joint" type="revolute">
    <origin rpy="-1.5708 0 0" xyz="0 0 0"/>
    <parent link="arm_5_link"/>
    <child link="arm_6_link"/>
    <axis xyz="0 0 1"/>
    <limit effort="20.1" lower="-2.947" upper="2.947" velocity="1.25"/>
    <!--safety_controller k_position="20" k_velocity="25" soft_lower_limit="${-2.09 + 0.01}" soft_upper_limit="${2.09 - 0.01}" /-->
  </joint>
  <link name="arm_6_link">
    <inertial>
      <mass value="0.29364"/>
      <inertia ixx="0.01" ixy="0" ixz="0" iyy="0.01" iyz="0" izz="0.01"/>
      <origin rpy="0 0 0" xyz="0 0 0"/>
    </inertial>
    <!--
      <inertial>
        <origin xyz="0 0 0" rpy="0 0 0"/>
        <mass value="0.819"/>
        <inertia ixx="0.01" ixy="0" ixz="0" iyy="0.01" iyz="0" izz="0.01" />
      </inertial>
-->
    <visual>
      <origin rpy="0 0 0" xyz="0 0 0"/>
      <geometry>
        <mesh filename="package://schunk_gripper_communication/meshes/lwa4p/arm_6_link.dae"/>
      </geometry>
      <material name="Schunk/DarkGrey"/>
    </visual>
    <collision>
      <origin rpy="0 0 0" xyz="0 0 0"/>
      <geometry>
        <mesh filename="package://schunk_gripper_communication/meshes/lwa4p/arm_6_link.stl"/>
      </geometry>
    </collision>
  </link>
  <!-- joint between arm_6_link and tcp_link -->
  <!--<joint name="${name}_tcp_joint" type="fixed">
      <origin xyz="0 0 0.08" rpy="0 0 0" />
      <parent link="${name}_6_link"/>
      <child link="${name}_tcp_link"/>
    </joint>
    <link name="${name}_tcp_link">
    </link>
    -->
  <joint name="gripper_joint" type="fixed">
    <origin rpy="0 0 0" xyz="0 0 0.32"/>
    <parent link="arm_6_link"/>
    <child link="gripper_link"/>
  </joint>
  <link name="gripper_link">
    <inertial>
      <origin rpy="0 0 0" xyz="0 0 0.13"/>
      <mass value="0.5"/>
      <inertia ixx="0.01" ixy="0" ixz="0" iyy="0.01" iyz="0" izz="0.01"/>
    </inertial>
    <visual>
      <origin rpy="0 0 0" xyz="0 0 -0.17"/>
      <geometry>
        <box size="0.1 0.1 0.13"/>
      </geometry>
      <material name="Schunk/Yellow"/>
    </visual>
    <collision>
      <origin rpy="0 0 0" xyz="0 0 -0.17"/>
      <geometry>
        <box size="0.1 0.1 0.13"/>
      </geometry>
    </collision>
  </link>
  <!-- joint between arm_6_link and tcp_link -->
  <joint name="arm_tcp_joint" type="fixed">
    <origin rpy="0 0 0" xyz="0 0 0.08"/>
    <parent link="gripper_link"/>
    <child link="arm_tcp_link"/>
  </joint>
  <link name="arm_tcp_link">
    </link>
  <gazebo reference="arm_0_link">
    <gravity>true</gravity>
    <self_collide>false</self_collide>
    <material value="Schunk/DarkGrey"/>
  </gazebo>
  <gazebo reference="arm_1_link">
    <gravity>true</gravity>
    <self_collide>false</self_collide>
    <material value="Schunk/DarkGrey"/>
  </gazebo>
  <gazebo reference="arm_2_link">
    <gravity>true</gravity>
    <self_collide>false</self_collide>
    <material value="Schunk/Blue"/>
  </gazebo>
  <gazebo reference="arm_3_link">
    <gravity>true</gravity>
    <self_collide>false</self_collide>
    <material value="Schunk/DarkGrey"/>
  </gazebo>
  <gazebo reference="arm_4_link">
    <gravity>true</gravity>
    <self_collide>false</self_collide>
    <material value="Schunk/Blue"/>
  </gazebo>
  <gazebo reference="arm_5_link">
    <gravity>true</gravity>
    <self_collide>false</self_collide>
    <material value="Schunk/DarkGrey"/>
  </gazebo>
  <gazebo reference="arm_6_link">
    <gravity>true</gravity>
    <self_collide>false</self_collide>
    <material value="Schunk/DarkGrey"/>
  </gazebo>
  <transmission name="arm_1_trans">
    <type>transmission_interface/SimpleTransmission</type>
    <joint name="arm_1_joint">
      <hardwareInterface>PositionJointInterface</hardwareInterface>
      <hardwareInterface>VelocityJointInterface</hardwareInterface>
    </joint>
    <actuator name="arm_1_motor">
      <mechanicalReduction>1</mechanicalReduction>
    </actuator>
  </transmission>
  <transmission name="arm_2_trans">
    <type>transmission_interface/SimpleTransmission</type>
    <joint name="arm_2_joint">
      <hardwareInterface>PositionJointInterface</hardwareInterface>
      <hardwareInterface>VelocityJointInterface</hardwareInterface>
    </joint>
    <actuator name="arm_2_motor">
      <mechanicalReduction>1</mechanicalReduction>
    </actuator>
  </transmission>
  <transmission name="arm_3_trans">
    <type>transmission_interface/SimpleTransmission</type>
    <joint name="arm_3_joint">
      <hardwareInterface>PositionJointInterface</hardwareInterface>
      <hardwareInterface>VelocityJointInterface</hardwareInterface>
    </joint>
    <actuator name="arm_3_motor">
      <mechanicalReduction>1</mechanicalReduction>
    </actuator>
  </transmission>
  <transmission name="arm_4_trans">
    <type>transmission_interface/SimpleTransmission</type>
    <joint name="arm_4_joint">
      <hardwareInterface>PositionJointInterface</hardwareInterface>
      <hardwareInterface>VelocityJointInterface</hardwareInterface>
    </joint>
    <actuator name="arm_4_motor">
      <mechanicalReduction>1</mechanicalReduction>
    </actuator>
  </transmission>
  <transmission name="arm_5_trans">
    <type>transmission_interface/SimpleTransmission</type>
    <joint name="arm_5_joint">
      <hardwareInterface>PositionJointInterface</hardwareInterface>
      <hardwareInterface>VelocityJointInterface</hardwareInterface>
    </joint>
    <actuator name="arm_5_motor">
      <mechanicalReduction>1</mechanicalReduction>
    </actuator>
  </transmission>
  <transmission name="arm_6_trans">
    <type>transmission_interface/SimpleTransmission</type>
    <joint name="arm_6_joint">
      <hardwareInterface>PositionJointInterface</hardwareInterface>
      <hardwareInterface>VelocityJointInterface</hardwareInterface>
    </joint>
    <actuator name="arm_6_motor">
      <mechanicalReduction>1</mechanicalReduction>
    </actuator>
  </transmission>
</robot>

